An error occurred while executing the following cell:
------------------
import matplotlib.pyplot as plt
from IPython.display import clear_output
from sklearn import datasets, preprocessing

try:
    import distrax
except ModuleNotFoundError:
    %pip install distrax
    import distrax
import jax
import jax.numpy as jnp
import numpy as np

try:
    import haiku as hk
except ModuleNotFoundError:
    %pip install haiku
    import haiku as hk
try:
    import optax
except ModuleNotFoundError:
    %pip install optax
    import optax
try:
    import tensorflow as tf
except ModuleNotFoundError:
    %pip install tensorflow
    import tensorflow as tf
try:
    import tensorflow_datasets as tfds
except ModuleNotFoundError:
    %pip install tensorflow tensorflow_datasets
    import tensorflow_datasets as tfds

try:
    from tensorflow_probability.substrates import jax as tfp
except ModuleNotFoundError:
    %pip install tensorflow-probability
    from tensorflow_probability.substrates import jax as tfp
tfd = tfp.distributions

# key = jax.random.PRNGKey(1234)
------------------

---------------------------------------------------------------------------
OSError                                   Traceback (most recent call last)
/tmp/ipykernel_2816/3748809266.py in <module>
     23     import optax
     24 try:
---> 25     import tensorflow as tf
     26 except ModuleNotFoundError:
     27     get_ipython().run_line_magic('pip', 'install tensorflow')

~/miniconda3/envs/py37/lib/python3.7/site-packages/tensorflow/__init__.py in <module>
     35 import typing as _typing
     36 
---> 37 from tensorflow.python.tools import module_util as _module_util
     38 from tensorflow.python.util.lazy_loader import LazyLoader as _LazyLoader
     39 

~/miniconda3/envs/py37/lib/python3.7/site-packages/tensorflow/python/__init__.py in <module>
     34 # pylint: disable=wildcard-import,g-bad-import-order,g-import-not-at-top
     35 
---> 36 from tensorflow.python import pywrap_tensorflow as _pywrap_tensorflow
     37 from tensorflow.python.eager import context
     38 

~/miniconda3/envs/py37/lib/python3.7/site-packages/tensorflow/python/pywrap_tensorflow.py in <module>
     24 
     25 # Perform pre-load sanity checks in order to produce a more actionable error.
---> 26 self_check.preload_check()
     27 
     28 # pylint: disable=wildcard-import,g-import-not-at-top,unused-import,line-too-long

~/miniconda3/envs/py37/lib/python3.7/site-packages/tensorflow/python/platform/self_check.py in preload_check()
     63     cpu_feature_guard_library = os.path.join(
     64         os.path.dirname(__file__), "../../core/platform/_cpu_feature_guard.so")
---> 65     ctypes.CDLL(cpu_feature_guard_library)

~/miniconda3/envs/py37/lib/python3.7/ctypes/__init__.py in __init__(self, name, mode, handle, use_errno, use_last_error)
    362 
    363         if handle is None:
--> 364             self._handle = _dlopen(self._name, mode)
    365         else:
    366             self._handle = handle

OSError: /github/home/miniconda3/envs/py37/lib/python3.7/site-packages/tensorflow/python/platform/../../core/platform/_cpu_feature_guard.so: cannot open shared object file: No such file or directory
OSError: /github/home/miniconda3/envs/py37/lib/python3.7/site-packages/tensorflow/python/platform/../../core/platform/_cpu_feature_guard.so: cannot open shared object file: No such file or directory
