An error occurred while executing the following cell:
------------------
data_iter, vocab = load_data_ptb(512, 5, 5)
for batch in data_iter:
    for name, data in zip(names, batch):
        print(name, "shape:", data.shape)
    break
------------------

---------------------------------------------------------------------------
AttributeError                            Traceback (most recent call last)
/tmp/ipykernel_3556/2666814423.py in <module>
----> 1 data_iter, vocab = load_data_ptb(512, 5, 5)
      2 for batch in data_iter:
      3     for name, data in zip(names, batch):
      4         print(name, "shape:", data.shape)
      5     break

/tmp/ipykernel_3556/4021376420.py in load_data_ptb(batch_size, max_window_size, num_noise_words)
      8     all_negatives = get_negatives(all_contexts, corpus, num_noise_words)
      9 
---> 10     class PTBDataset(torch.utils.data.Dataset):
     11         def __init__(self, centers, contexts, negatives):
     12             assert len(centers) == len(contexts) == len(negatives)

AttributeError: module 'torch' has no attribute 'utils'
AttributeError: module 'torch' has no attribute 'utils'
