An error occurred while executing the following cell:
------------------


import numpy as np
import matplotlib.pyplot as plt
import os
try:
    import pyprobml_utils as pml
except ModuleNotFoundError:
    %pip install pyprobml_utils
    import pyprobml_utils as pml

from scipy.stats import gaussian_kde
from scipy.stats import norm
np.random.seed(42)

x = np.arange(0.5, 2.5, 0.01)
for size in [10, 100, 1000]:
    samples = norm.rvs(loc=1.5, scale=0.5, size=size)
    y = norm.pdf(x, loc=1.5, scale=0.5)

    plt.figure()
    #plt.hist(samples, normed=True, rwidth=0.8)
    plt.hist(samples, density=True, rwidth=0.8)
    plt.plot(x, y, 'r')
    plt.xlim(0, 3)
    plt.title('n_samples = %d' % size)
    save_fig('mcAccuracyDemoHist%d.pdf' % size)

    kde = gaussian_kde(samples)
    y_estimate = kde(x)
    plt.figure()
    plt.plot(x, y, 'r', label='true pdf')
    plt.plot(x, y_estimate, 'b--', label='estimated pdf')
    plt.legend()
    plt.title('n_samples = %d' % size)
    pml.savefig('mcAccuracyDemoKde%d.pdf' % size)
plt.show()

------------------

---------------------------------------------------------------------------
ModuleNotFoundError                       Traceback (most recent call last)
/tmp/ipykernel_2762/4033161307.py in <module>
      4 try:
----> 5     import pyprobml_utils as pml
      6 except ModuleNotFoundError:

ModuleNotFoundError: No module named 'pyprobml_utils'

During handling of the above exception, another exception occurred:

ModuleNotFoundError                       Traceback (most recent call last)
/tmp/ipykernel_2762/4033161307.py in <module>
      6 except ModuleNotFoundError:
      7     get_ipython().run_line_magic('pip', 'install pyprobml_utils')
----> 8     import pyprobml_utils as pml
      9 
     10 from scipy.stats import gaussian_kde

ModuleNotFoundError: No module named 'pyprobml_utils'
ModuleNotFoundError: No module named 'pyprobml_utils'
